<?xml version="1.0" encoding="utf-8"?>
<!-- This URDF was automatically created by SolidWorks to URDF Exporter! Originally created by Stephen Brawner (brawner@gmail.com) 
     Commit Version: 1.5.1-0-g916b5db  Build Version: 1.5.7152.31018
     For more information, please see http://wiki.ros.org/sw_urdf_exporter -->
<robot
  name="stoch_4_urdf">
  <link
    name="base_link">
    <inertial>
      <origin
        xyz="-0.10238 -1.8464E-05 0.0026538"
        rpy="0 0 0" />
      <mass
        value="7.3" />
      <inertia
        ixx="0.0090197"
        ixy="2.2679E-06"
        ixz="6.4897E-05"
        iyy="0.0094033"
        iyz="-2.1628E-08"
        izz="0.01573" />
    </inertial>
    <visual>
      <origin
        xyz="0 0 0"
        rpy="0 0 0" />
      <geometry>
      
        <mesh
          filename="package://stoch_4_urdf/meshes/base_link.STL" />
      </geometry>
      <material
        name="red">
        <color
          rgba="1 0 0 1" />
      </material>
    </visual>
    <collision>
      <origin
        xyz="0 0 0"
        rpy="0 0 0" />
      <geometry>
        <mesh
          filename="package://stoch_4_urdf/meshes/base_link.STL" />
      </geometry>
    </collision>
  </link>
  <link
    name="FL_Link">
    <inertial>
      <origin
        xyz="0.070269 -0.036118 -2.5973E-07"
        rpy="0 0 0" />
      <mass
        value="0.978" />
      <inertia
        ixx="0.00045941"
        ixy="-6.723E-07"
        ixz="3.3247E-08"
        iyy="0.00059328"
        iyz="5.8817E-09"
        izz="0.00046214" />
    </inertial>
    <visual>
      <origin
        xyz="0 0 0"
        rpy="0 0 0" />
      <geometry>
        <mesh
          filename="package://stoch_4_urdf/meshes/FL_Link.STL" />
      </geometry>
      <material
        name="black">
        <color
          rgba="0 0 0 1" />
      </material>
    </visual>
    <collision>
      <origin
        xyz="0 0 0"
        rpy="0 0 0" />
      <geometry>
        <mesh
          filename="package://stoch_4_urdf/meshes/FL_Link.STL" />
      </geometry>
    </collision>
  </link>
  <joint
    name="FL_Joint"
    type="revolute">
    <origin
      xyz="0.18598 0.10004 -0.0005"
      rpy="0 0 0.00021134" />
    <parent
      link="base_link" />
    <child
      link="FL_Link" />
    <axis
      xyz="1 0 0" />
    <limit
      lower="-1.5708"
      upper="1.5708"
      effort="100"
      velocity="100" />
  </joint>
  <link
    name="FLKM_Link">
    <inertial>
      <origin
        xyz="-0.072527 0.076425 1.3632E-05"
        rpy="0 0 0" />
      <mass
        value="1.547" />
      <inertia
        ixx="0.00031538"
        ixy="-4.0486E-06"
        ixz="-4.8939E-07"
        iyy="0.0031011"
        iyz="6.4773E-11"
        izz="0.0028703" />
    </inertial>
    <visual>
      <origin
        xyz="0 0 0"
        rpy="0 0 0" />
      <geometry>
        <mesh
          filename="package://stoch_4_urdf/meshes/FLKM_Link.STL" />
      </geometry>
      <material
        name="black">
        <color
          rgba="0 0 0 1" />
      </material>
    </visual>
    <collision>
      <origin
        xyz="0 0 0"
        rpy="0 0 0" />
      <geometry>
        <mesh
          filename="package://stoch_4_urdf/meshes/FLKM_Link.STL" />
      </geometry>
    </collision>
  </link>
  <joint
    name="FLKM_Joint"
    type="revolute">
    <origin
      xyz="0.074 -0.01975 0"
      rpy="0 0 0" />
    <parent
      link="FL_Link" />
    <child
      link="FLKM_Link" />
    <axis
      xyz="0 -1 0" />
    <limit
      lower="-1.5708"
      upper="6.2832"
      effort="100"
      velocity="100" />
  </joint>
  <link
    name="FLK_Link">
    <inertial>
      <origin
        xyz="0.18227 2.469E-07 -0.017857"
        rpy="0 0 0" />
      <mass
        value="0.2" />
      <inertia
        ixx="2.1525E-05"
        ixy="-8.02E-10"
        ixz="2.6374E-05"
        iyy="0.00042744"
        iyz="-2.0344E-10"
        izz="0.00040935" />
    </inertial>
    <visual>
      <origin
        xyz="0 0 0"
        rpy="0 0 0" />
      <geometry>
        <mesh
          filename="package://stoch_4_urdf/meshes/FLK_Link.STL" />
      </geometry>
      <material
        name="black">
        <color
          rgba="0 0 0 1" />
      </material>
    </visual>
    <collision>
      <origin
        xyz="0 0 0"
        rpy="0 0 0" />
      <geometry>
        <mesh
          filename="package://stoch_4_urdf/meshes/FLK_Link.STL" />
      </geometry>
    </collision>
  </link>
  <joint
    name="FLK_Joint"
    type="continuous">
    <origin
      xyz="-0.297 0.1385 0"
      rpy="0 0 0" />
    <parent
      link="FLKM_Link" />
    <child
      link="FLK_Link" />
    <axis
      xyz="0 1 0" />
    <limit
      lower="0"
      upper="0"
      effort="0"
      velocity="0" />
  </joint>
  <link
    name="FR_Link">
    <inertial>
      <origin
        xyz="0.07027 0.036118 -2.9553E-07"
        rpy="0 0 0" />
      <mass
        value="0.978" />
      <inertia
        ixx="0.00045941"
        ixy="6.965E-07"
        ixz="-3.3418E-08"
        iyy="0.00059328"
        iyz="-5.8767E-09"
        izz="0.00046214" />
    </inertial>
    <visual>
      <origin
        xyz="0 0 0"
        rpy="0 0 0" />
      <geometry>
        <mesh
          filename="package://stoch_4_urdf/meshes/FR_Link.STL" />
      </geometry>
      <material
        name="black">
        <color
          rgba="0 0 0 1" />
      </material>
    </visual>
    <collision>
      <origin
        xyz="0 0 0"
        rpy="0 0 0" />
      <geometry>
        <mesh
          filename="package://stoch_4_urdf/meshes/FR_Link.STL" />
      </geometry>
    </collision>
  </link>
  <joint
    name="FR_Joint"
    type="revolute">
    <origin
      xyz="0.18602 -0.099961 -0.0005"
      rpy="0 0 0.00021134" />
    <parent
      link="base_link" />
    <child
      link="FR_Link" />
    <axis
      xyz="1 0 0" />
    <limit
      lower="-1.5708"
      upper="1.5708"
      effort="100"
      velocity="100" />
  </joint>
  <link
    name="FRKM_Link">
    <inertial>
      <origin
        xyz="-0.072527 -0.076425 -1.3633E-05"
        rpy="0 0 0" />
      <mass
        value="1.547" />
      <inertia
        ixx="0.00031538"
        ixy="4.0486E-06"
        ixz="4.8938E-07"
        iyy="0.0031011"
        iyz="6.4797E-11"
        izz="0.0028703" />
    </inertial>
    <visual>
      <origin
        xyz="0 0 0"
        rpy="0 0 0" />
      <geometry>
        <mesh
          filename="package://stoch_4_urdf/meshes/FRKM_Link.STL" />
      </geometry>
      <material
        name="black">
        <color
          rgba="0 0 0 1" />
      </material>
    </visual>
    <collision>
      <origin
        xyz="0 0 0"
        rpy="0 0 0" />
      <geometry>
        <mesh
          filename="package://stoch_4_urdf/meshes/FRKM_Link.STL" />
      </geometry>
    </collision>
  </link>
  <joint
    name="FRKM_Joint"
    type="revolute">
    <origin
      xyz="0.074 0.01975 0"
      rpy="0 0 0" />
    <parent
      link="FR_Link" />
    <child
      link="FRKM_Link" />
    <axis
      xyz="0 1 0" />
    <limit
      lower="-1.5708"
      upper="6.2832"
      effort="100"
      velocity="100" />
  </joint>
  <link
    name="FRK_Link">
    <inertial>
      <origin
        xyz="0.18227 2.469E-07 -0.017857"
        rpy="0 0 0" />
      <mass
        value="0.2" />
      <inertia
        ixx="2.1525E-05"
        ixy="-8.02E-10"
        ixz="2.6374E-05"
        iyy="0.00042744"
        iyz="-2.0344E-10"
        izz="0.00040935" />
    </inertial>
    <visual>
      <origin
        xyz="0 0 0"
        rpy="0 0 0" />
      <geometry>
        <mesh
          filename="package://stoch_4_urdf/meshes/FRK_Link.STL" />
      </geometry>
      <material
        name="black">
        <color
          rgba="0 0 0 1" />
      </material>
    </visual>
    <collision>
      <origin
        xyz="0 0 0"
        rpy="0 0 0" />
      <geometry>
        <mesh
          filename="package://stoch_4_urdf/meshes/FRK_Link.STL" />
      </geometry>
    </collision>
  </link>
  <joint
    name="FRK_Joint"
    type="continuous">
    <origin
      xyz="-0.297 -0.1385 0"
      rpy="0 0 0" />
    <parent
      link="FRKM_Link" />
    <child
      link="FRK_Link" />
    <axis
      xyz="0 -1 0" />
    <limit
      lower="0"
      upper="0"
      effort="0"
      velocity="0" />
  </joint>
  <link
    name="BL_Link">
    <inertial>
      <origin
        xyz="-0.06995 -0.037322 -1.8681E-06"
        rpy="0 0 0" />
      <mass
        value="0.978" />
      <inertia
        ixx="0.00039025"
        ixy="5.9364E-08"
        ixz="1.1626E-07"
        iyy="0.00050148"
        iyz="5.3635E-09"
        izz="0.00037524" />
    </inertial>
    <visual>
      <origin
        xyz="0 0 0"
        rpy="0 0 0" />
      <geometry>
        <mesh
          filename="package://stoch_4_urdf/meshes/BL_Link.STL" />
      </geometry>
      <material
        name="black">
        <color
          rgba="0 0 0 1" />
      </material>
    </visual>
    <collision>
      <origin
        xyz="0 0 0"
        rpy="0 0 0" />
      <geometry>
        <mesh
          filename="package://stoch_4_urdf/meshes/BL_Link.STL" />
      </geometry>
    </collision>
  </link>
  <joint
    name="BL_Joint"
    type="revolute">
    <origin
      xyz="-0.18602 0.099961 -0.0005"
      rpy="0 0 0.00021134" />
    <parent
      link="base_link" />
    <child
      link="BL_Link" />
    <axis
      xyz="-1 0 0" />
    <limit
      lower="-1.5708"
      upper="1.5708"
      effort="100"
      velocity="100" />
  </joint>
  <link
    name="BLKM_Link">
    <inertial>
      <origin
        xyz="-0.072527 0.076425 1.3632E-05"
        rpy="0 0 0" />
      <mass
        value="1.547" />
      <inertia
        ixx="0.00031538"
        ixy="-4.0486E-06"
        ixz="-4.8939E-07"
        iyy="0.0031011"
        iyz="6.4774E-11"
        izz="0.0028703" />
    </inertial>
    <visual>
      <origin
        xyz="0 0 0"
        rpy="0 0 0" />
      <geometry>
        <mesh
          filename="package://stoch_4_urdf/meshes/BLKM_Link.STL" />
      </geometry>
      <material
        name="black">
        <color
          rgba="0 0 0 1" />
      </material>
    </visual>
    <collision>
      <origin
        xyz="0 0 0"
        rpy="0 0 0" />
      <geometry>
        <mesh
          filename="package://stoch_4_urdf/meshes/BLKM_Link.STL" />
      </geometry>
    </collision>
  </link>
  <joint
    name="BLKM_Joint"
    type="revolute">
    <origin
      xyz="-0.074 -0.01975 0"
      rpy="0 0 0" />
    <parent
      link="BL_Link" />
    <child
      link="BLKM_Link" />
    <axis
      xyz="0 -1 0" />
    <limit
      lower="-1.5708"
      upper="6.2832"
      effort="100"
      velocity="100" />
  </joint>
  <link
    name="BLK_Link">
    <inertial>
      <origin
        xyz="0.18227 2.469E-07 -0.017857"
        rpy="0 0 0" />
      <mass
        value="0.2" />
      <inertia
        ixx="2.1525E-05"
        ixy="-8.02E-10"
        ixz="2.6374E-05"
        iyy="0.00042744"
        iyz="-2.0344E-10"
        izz="0.00040935" />
    </inertial>
    <visual>
      <origin
        xyz="0 0 0"
        rpy="0 0 0" />
      <geometry>
        <mesh
          filename="package://stoch_4_urdf/meshes/BLK_Link.STL" />
      </geometry>
      <material
        name="black">
        <color
          rgba="0 0 0 1" />
      </material>
    </visual>
    <collision>
      <origin
        xyz="0 0 0"
        rpy="0 0 0" />
      <geometry>
        <mesh
          filename="package://stoch_4_urdf/meshes/BLK_Link.STL" />
      </geometry>
    </collision>
  </link>
  <joint
    name="BLK_Joint"
    type="continuous">
    <origin
      xyz="-0.297 0.1385 0"
      rpy="0 0 0" />
    <parent
      link="BLKM_Link" />
    <child
      link="BLK_Link" />
    <axis
      xyz="0 1 0" />
    <limit
      lower="0"
      upper="0"
      effort="0"
      velocity="0" />
  </joint>
  <link
    name="BR_Link">
    <inertial>
      <origin
        xyz="-0.070173 0.037288 -1.5868E-07"
        rpy="0 0 0" />
      <mass
        value="0.978" />
      <inertia
        ixx="0.00038996"
        ixy="-9.0848E-07"
        ixz="-8.0338E-08"
        iyy="0.00050185"
        iyz="-1.0951E-09"
        izz="0.00037578" />
    </inertial>
    <visual>
      <origin
        xyz="0 0 0"
        rpy="0 0 0" />
      <geometry>
        <mesh
          filename="package://stoch_4_urdf/meshes/BR_Link.STL" />
      </geometry>
      <material
        name="black">
        <color
          rgba="0 0 0 1" />
      </material>
    </visual>
    <collision>
      <origin
        xyz="0 0 0"
        rpy="0 0 0" />
      <geometry>
        <mesh
          filename="package://stoch_4_urdf/meshes/BR_Link.STL" />
      </geometry>
    </collision>
  </link>
  <joint
    name="BR_Joint"
    type="revolute">
    <origin
      xyz="-0.18598 -0.10004 -0.0005"
      rpy="0 0 0.00021134" />
    <parent
      link="base_link" />
    <child
      link="BR_Link" />
    <axis
      xyz="-1 0 0" />
    <limit
      lower="-1.5708"
      upper="1.5708"
      effort="100"
      velocity="100" />
  </joint>
  <link
    name="BRKM_Link">
    <inertial>
      <origin
        xyz="-0.072527 -0.076425 -1.3633E-05"
        rpy="0 0 0" />
      <mass
        value="1.547" />
      <inertia
        ixx="0.00031538"
        ixy="4.0486E-06"
        ixz="4.8938E-07"
        iyy="0.0031011"
        iyz="6.4788E-11"
        izz="0.0028703" />
    </inertial>
    <visual>
      <origin
        xyz="0 0 0"
        rpy="0 0 0" />
      <geometry>
        <mesh
          filename="package://stoch_4_urdf/meshes/BRKM_Link.STL" />
      </geometry>
      <material
        name="black">
        <color
          rgba="0 0 0 1" />
      </material>
    </visual>
    <collision>
      <origin
        xyz="0 0 0"
        rpy="0 0 0" />
      <geometry>
        <mesh
          filename="package://stoch_4_urdf/meshes/BRKM_Link.STL" />
      </geometry>
    </collision>
  </link>
  <joint
    name="BRKM_Joint"
    type="revolute">
    <origin
      xyz="-0.074 0.01975 0"
      rpy="0 0 0" />
    <parent
      link="BR_Link" />
    <child
      link="BRKM_Link" />
    <axis
      xyz="0 1 0" />
    <limit
      lower="-1.5708"
      upper="6.2832"
      effort="100"
      velocity="100" />
  </joint>
  <link
    name="BRK_Link">
    <inertial>
      <origin
        xyz="0.18227 2.469E-07 -0.017857"
        rpy="0 0 0" />
      <mass
        value="0.2" />
      <inertia
        ixx="2.1525E-05"
        ixy="-8.02E-10"
        ixz="2.6374E-05"
        iyy="0.00042744"
        iyz="-2.0344E-10"
        izz="0.00040935" />
    </inertial>
    <visual>
      <origin
        xyz="0 0 0"
        rpy="0 0 0" />
      <geometry>
        <mesh
          filename="package://stoch_4_urdf/meshes/BRK_Link.STL" />
      </geometry>
      <material
        name="black">
        <color
          rgba="0 0 0 1" />
      </material>
    </visual>
    <collision>
      <origin
        xyz="0 0 0"
        rpy="0 0 0" />
      <geometry>
        <mesh
          filename="package://stoch_4_urdf/meshes/BRK_Link.STL" />
      </geometry>
    </collision>
  </link>
  <joint
    name="BRK_Joint"
    type="continuous">
    <origin
      xyz="-0.297 -0.1385 0"
      rpy="0 0 0" />
    <parent
      link="BRKM_Link" />
    <child
      link="BRK_Link" />
    <axis
      xyz="0 -1 0" />
    <limit
      lower="0"
      upper="0"
      effort="0"
      velocity="0" />
  </joint>


</robot>